# 01. 구문 오류와 예외
- 괄호 개수를 잘못 입력하는 등의 코드가 실행조차 되지 않는 오류를 구문 오류(Syntax Error). 이러한 문법적 오류를 제외하고 코드 실행 중간에 발생하는 오류를 예외(exception)이라 함. 그리고 이를 처리하는
것을 예외 처리(exception handling)이라 함.

## 오류의 종류
- 오류(error)의 종류에는 크게 2가지
1. 프로그램 실행 전에 발생하는 오류
2. 프로그램 실행 중에 발생하는 오류
- 2가지 모두 '오류'. 프로그램 실행 전에 발생하는 오류를 구문 오류(Syntax Error), 프로그램 실행 중에 발생하는 오류를 예외(exception) 또는 런타임 오류(runtime error)라 구분하여 부름.

### 구문 오류
- 구문 오류가 있으면 웹 브라우저가 코드를 분석조차 하지 못하므로 실행되지 않음.
- 간단하게 구문 오류를 발생시켜보자.
```js
console.log("# 프로그램이 시작되었습니다.")

// 구문 오류가 발생하는 부분.
console.log("괄호를 닫지 않는 실수를 했습니다."
```
- 콘솔을 보면 Syntax Error를 확인할 수 있음. 구문 오류라는 의미.
```text
Uncaught SyntaxError: missing ) after argument list
```
- 구문 오류는 실행 전에 웹 브라우저가 "제가 코드를 읽어봤는데 이런 곳에 문제가 있어서 실행조차 안 됩니다. 해결해주면 좋곘습니다"라는 형태로 오류의 위치를 사전에 정확하게 짚어서 알려줌. 따라서 쉽게 해결할 수
있는 오류에 속함.

## 예외
- 예외(exception) 또는 런타임 오류(runtime error)는 실행 중에 발생하는 오류. 예를 들어 보자.
```js
console.log("# 프로그램이 시작되었습니다!")

// 구문 오류가 발생하는 부분.
console.rog("log를 rog로 잘못 입력했습니다.")
```
- 콘솔을 살펴보면 오류를 출력함. 하지만 이전 코드와 다르게 앞의 문자열을 출력함. 즉, 일단 코드는 실행됨.
```text
Uncaught TypeError: console.rog is not a function
    at <anonymous>:4:9
```
- console.rog() 줄을 읽는 순간 rog 라는 식별자가 없어서 undefined 인데 이를 함수 호출 형태로 사용하니 "console.rog는 함수가 아니에요."라고 오류를 출력하는 것.
- 이처럼 실행 중에 발생하는 오류가 예외. js에서는 SyntaxError라고 출력되는 오류 이외의 모든 오류(TypeError, ReferenceError, RangeError)가 예외로 분류됨.
- 현재 코드의 예외는 오탈자 수정으로 간단히 수정 가능. 그런데 예외 중에는 오탈자를 고치는 것만으로는 해결할 수 없는 예외도 존재.

## 기본 예외 처리
- 조건문을 사용해서 예외가 발생하지 않게 만드는 것을 기본 예외 처리라고 부름. 
- 다음 코드는 querySelector() 메소드로 문서 객체를 추출한 뒤 textContent 속성에 글자를 할당하는 코드인데 body 태그 내부에 h1 태그가 없음. 따라서 예외가 발생함.
```html
<body>

</body>
<script>
    document.addEventListener('DOMContentLoaded', () => {
        const h1 = document.querySelector('h1')
        h1.textContent = '안녕하세요.'
    })
</script>
```
```text
Uncaught TypeError: Cannot set properties of null (setting 'textContent')
    at HTMLDocument.<anonymous>
```
- 문서 객체를 선택했는데 문서 객체가 없는 경우라면, 다음과 같이 조건문으로 h1이 존재하는 경우에만 textContent 속성을 변경하도록 예외 처리를 할 수 있음.
```html
<body>

</body>
<script>
    document.addEventListener('DOMContentLoaded', () => {
        const h1 = document.querySelector('h1')
        if (h1) {
            h1.textContent = '안녕하세요.'
        } else {
            console.log('h1 태그를 추출할 수 없습니다.')
        }
    })
</script>
```
```text
h1 태그를 추출할 수 없습니다.
```
- js는 다른 프로그래밍 언어들에 비해 유연해 예외를 발생할 가능성이 적은 편. 예를 들어 js는 배열의 길이를 넘는 위치 선택시 오류가 아닌 undefined 출력.
- 이와 같이 유연함 때문에 예외를 발생하지 않는다고 좋은 것은 아님. 프로그램에 문제가 발생했는데도 죽지 않고 실행되면 계속해서 문제를 만들 가능성 존재.
- 따라서 문제가 발생할 수 있는 부분은 조건문 등으로 처리해주어야 함.

## 고급 예외 처리
- 예외를 조금 더 쉽게 잡을 수 있는 기능으로 try catch finally 구문 존재.
- 이와 같은 try catch finally 구문을 사용해서 예외를 처리하는 방법을 고급 예외 처리라고 부름,
- try catch finally 구문의 기본적인 형태.
```js
try {
    // 예외가 발생할 가능성이 있는 코드
} catch () {
    // 예외가 발생했을 때 실행할 코드
} finally {
    // 무조건 실행할 코드 (필요한 경우에만 사용)
}
```
- try 안에서 예외를 발생하면 이를 catch 구문에서 처리함. finally 구문은 필수가 아니며 예외 발생 여부와 상관없이 수행해야 하는 작업이 있을 때 사용.
- try 구문 안에서 예외가 발생하면 더 이상 try 구문을 진행하지 않고 catch 구문을 실행함. 다음 구문은 console.log를 출력하지 않음.
```js
try {
    willExcept.byeBye()
    console.log('try 구문의 마지막 줄')
} catch () {
    console.log('catch 구문의 마지막 줄')
}
```
```text
catch 구문의 마지막 줄
```
- finally 구문은 무조건 실행되는 것을 아래 코드로 알아볼 수 있습니다.
```js
try {
    willExcept.byeBye()
    console.log('try 구문의 마지막 줄')
} catch (exception) {
    console.log('catch 구문의 마지막 줄')
} finally {
    console.log('finally 구문의 마지막 줄')
}
```
```text
catch 구문의 마지막 줄
finally 구문의 마지막 줄
```
- try 구문에서 예외가 발생하고 catch 구문이 실행됨. try 구문에서 예외가 발생하든 안 하든 무조건 finally 구문은 실행됨.

## finally 구문을 사용하는 이유
- 예외 처리 구문 내부에서 return 사용하기
```js
function test1() {
    console.log('============ test1 ============')
    try {
        console.log('A 위치입니다.')
        throw '예외 강제 발생'
    } catch (exception) {
        console.log('B 위치입니다.')
        return
    }
    console.log('C 위치입니다.')
}

test1()

function test2() {
    console.log('============ test2 ============')
    try {
        console.log('A 위치입니다.')
        throw '예외 강제 발생'
    } catch (exception) {
        console.log('B 위치입니다.')
        return
    } finally {
        console.log('C 위치입니다.')
    }
}

test2()
```
```text
============ test1 ============
A 위치입니다.
B 위치입니다.
============ test2 ============
A 위치입니다.
B 위치입니다.
C 위치입니다.
```
- finally 구문을 반드시 실행한다는 특성 때문에 test2()에서는 C 위치도 출력되었음.
- 이처럼 다음과 같은 경우에 결과가 달라짐.
1. try catch 구문 내부에서 return 키워드를 만날 때
2. try catch 구문 내부에서 break 또는 continue 키워드를 만날 때
- Node.js 처럼 서버로 사용하는 js에서는 이러한 내용을 알아야 안전하게 코드를 작성할 수 있음.

## 핵심 정리
- 구문 오류는 프로그램 실행 전에 발생하는 코드의 문법적인 문제로 발생하는 오류를 의미함.
- 예외는 프로그램 실행 중에 발생하는 모든 오류를 의미함.
- 예외 처리는 예외가 발생했을 때 프로그램이 중단되지 않게 하는 처리. 구문 오류는 예외 처리로 처리할 수 없음.
- try catch finally 구문은 try 구문 안에서 예외가 발생하면 catch 구문에서 처리하고, finally 구문은 예외 발생 여부와 상관없이 실행해야 하는 작업이 있을 때 사용함.
