# 8.2 예외 처리 고급
- 프로그래밍 언어에서 예외가 발생하면 예외와 발생된 정보를 확인할 수 있음. 이러한 정보를 확인할 수 있게 해주는 것이 예외 객체(exception object).
- 예외를 갖에로 발생시킬 때 throw 키워드 사용

## 예외 객체
- try catch 구문 사용시 catch 괄호 안에 입력하는 식별자가 예외 객체(exception object). 아무 식별자나 입력해도 괜찮지만 e 나 exception 식별자 사용.
- 예외 객체가 갖고 있는 속성은 브라우저에 따라 조금씩 다름. 모든 웹 브라우저가 공통적으로 갖고 있는 속성을 정리하면 아래와 같음.

| 속성 이름   | 설명     |
|---------|--------|
| name    | 예외 이름  |
| message | 예외 메시지 |

```js
try {
    const array = new Array(9999999999999999)
} catch (exception) {
    console.log(exception)
    console.log()
    console.log(`예외 이름 : ${exception.name}`)
    console.log(`예외 메시지 : ${exception.message}`)
}
```
```text
RangeError: Invalid array length
    at Object.<anonymous> (/Users/kimjihun/dev/HongongJS/code/chap08/exceptionInfo.js:3:19)
    ...

예외 이름 : RangeError
예외 메시지 : Invalid array length
```
- 이후에 js를 사용해 데스크톱 또는 모바일 애플리케이션 등을 만든다면 사용자가 애플리케이션을 사용하는 중 예외가 발생했을 때, 어떤 예외가 발생했는지 예외 객체의 내용을 웹 요청과 메일 등으로 전달받을 수 있게
구현 가능. 사용자로부터 받은 예외 객체의 내용을 기반으로 어떤 오류가 발생햇는지 확인하고 대처 가능.

## 예외 강제 발생
- 상황에 따라 예외를 강제로 발생시켜야 하는 경우도 존재. 예외를 강제로 발생시킬 떄는 throw 키워드를 사용. throw 구문의 형식.
```js
// 단순하게 예외를 발생시킴.
throw 문자열

// 조금 더 자세하게 예외를 발생시킴.
throw new Error(문자열)
```
- js 콘솔에서 사용하면 아래와 같음. throw 구문을 사용하면 곧바로 예외를 발생시킴. 코드 실행 중에 throw 키워드를 사용하면 예외를 발생하므로 프로그램이 중단됨.
```text
> throw '문자열'
Uncaught 문자열

> throw new Error('문자열')
Uncaught Error: 문자열
    at <anonymous>:1:7
```
- 단순하게 문자열을 입력한 경우와 new Error() 형태의 코드를 사용한 경우의 출력이 약간 다름. 2가지 모두 많이 사용됨.
- throw 구문을 사용하는 예제.
```js
function divide(a, b) {
    if (b === 0) {
        throw '0으로 나눌 수 없습니다.'
    }
    return a / b
}

console.log(divide(10, 2))
console.log(divide(10, 0))
```
```text
5

divide.js:4
        throw '0으로 나눌 수 없습니다.'
        ^
0으로 나눌 수 없습니다.
(Use `node --trace-uncaught ...` to show where the exception was thrown)
```
- 예외를 강제로 발생시키는 이유는 무엇일까? 일반적으로 개발을 할 때는 어떤 사람이 라이브러리처럼 다양한 기능을 가진 유틸리티 함수(또는 클래스)를 만들고, 다른 사람들이 그러한 라이브러리의 함수(또는 클래스)를
활용하는 경우가 많음.
- 내가 만든 함수를 내가 사용할 때는 아무 문제없이 사용할 수 있겠지만, 내가 만든 함수를 다른 사람이 사용할 때는 내가 의도하지 않은 형태로 코드를 사용할 수도 있음. 이럴 때 예외를 강제로 발생시키면 사용자에게
주의를 줄 수 있으며, 의도한 대로 처리하게 유도할 수도 있음.
- 다음과 같이 예외를 강제로 발생시켜야 하는 코드의 실행 결과를 예측해보자.
```js
function test(object) {
    console.log(object.a + object.b)
}

test({})
```
```text
NaN
```
- 일반적인 프로그래밍 언어라면
  - object 객체에 a 속성과 b 속성이 없으므로 예외를 발생할 것이고,
  - 존재하지 않는 것을 더하므로 object.a + object.b 를 할 때도 예외를 발생함.
- 그러면 사용자는 자신이 잘못 사용했다는 것을 인지하고 수정할 수 있음.
- 하지만 js는
  - object.a 가 undefined로 나오며, object.b 도 undefined로 나옴.
  - 여기에서 undefined + undefined 를 하면 NaN 이 나옴.
- 즉, 아무 오류 없이 코드가 정상적으로 실행됨.
- 그렇기 때문에 강제로라도 인지시켜줄 필요가 존재. 위의 코드를 안전하게 사용하려면 다음과 같이 예외를 강제로 발생시켜주면 됨.
```js
function test(object) {
    if (object.a !== undefined && object.b !== undefined) {
        console.log(object.a + object.b)
    } else {
        throw new Error('a 속성과 b 속성을 지정하지 않았습니다.')
    }
}

test({})
```
```text
/Users/kimjihun/dev/HongongJS/code/chap08/throwException.js:13
        throw new Error('a 속성과 b 속성을 지정하지 않았습니다.')
        ^

Error: a 속성과 b 속성을 지정하지 않았습니다.
    at test2 (/Users/kimjihun/dev/HongongJS/code/chap08/throwException.js:13:15)
    at Object.<anonymous> (/Users/kimjihun/dev/HongongJS/code/chap08/throwException.js:17:1)
    at Module._compile (node:internal/modules/cjs/loader:1256:14)
    at Module._extensions..js (node:internal/modules/cjs/loader:1310:10)
    at Module.load (node:internal/modules/cjs/loader:1119:32)
    at Module._load (node:internal/modules/cjs/loader:960:12)
    at Function.executeUserEntryPoint [as runMain] (node:internal/modules/run_main:81:12)
    at node:internal/main/run_main_module:23:47
```
- 이렇게 코드를 작성하면 사용자가 코드의 문제점을 인지하고 해결할 수 있음.

## 핵심 정리
- 예외 객체는 예외와 관련된 정보를 담응 객체를 의미.
- throw 구문은 예외를 강제로 발생시킬 때 사용하는 구문.

